<sdf version="1.7">
  <model name="Assem1">
    <link name="base_link">
      <inertial>
        <pose>-0.000565 0.000565 0.042565 0 -0 0</pose>
        <mass>0.20107</mass>
        <inertia>
          <ixx>0.00020365</ixx>
          <ixy>-2.8167e-06</ixy>
          <ixz>-1.6706e-06</ixz>
          <iyy>0.00020365</iyy>
          <iyz>1.6706e-06</iyz>
          <izz>0.00033331</izz>
        </inertia>
      </inertial>
      <collision name="base_link_collision">
        <pose>0 0 0 0 -0 0</pose>
        <geometry>
          <mesh>
            <scale>1 1 1</scale>
            <uri>package://urdf_4/meshes/visual/base_link.STL</uri>
          </mesh>
        </geometry>
      </collision>
      <visual name="base_link_visual">
        <pose>0 0 0 0 -0 0</pose>
        <geometry>
          <mesh>
            <scale>1 1 1</scale>
            <uri>package://urdf_4/meshes/visual/base_link.STL</uri>
          </mesh>
        </geometry>
      </visual>
    </link>
    <joint name="Joint_1" type="revolute">
      <pose relative_to="base_link">0 0 0 0 -0 0</pose>
      <parent>base_link</parent>
      <child>Link_1</child>
      <axis>
        <xyz>0 0 -1</xyz>
        <limit>
          <lower>-1.571</lower>
          <upper>1.571</upper>
          <effort>300</effort>
          <velocity>3</velocity>
        </limit>
        <dynamics>
          <spring_reference>0</spring_reference>
          <spring_stiffness>0</spring_stiffness>
        </dynamics>
      </axis>
    </joint>
    <link name="Link_1">
      <pose relative_to="Joint_1">0 0 0 0 -0 0</pose>
      <inertial>
        <pose>-0.000172 -0.000173 0.11465 0 -0 0</pose>
        <mass>0.17103</mass>
        <inertia>
          <ixx>0.00019137</ixx>
          <ixy>2.9717e-05</ixy>
          <ixz>-7.4593e-06</ixz>
          <iyy>0.00017798</iyy>
          <iyz>-6.1658e-06</iyz>
          <izz>0.00012482</izz>
        </inertia>
      </inertial>
      <collision name="Link_1_collision">
        <pose>0 0 0 0 -0 0</pose>
        <geometry>
          <mesh>
            <scale>1 1 1</scale>
            <uri>package://urdf_4/meshes/visual/Link_1.STL</uri>
          </mesh>
        </geometry>
      </collision>
      <visual name="Link_1_visual">
        <pose>0 0 0 0 -0 0</pose>
        <geometry>
          <mesh>
            <scale>1 1 1</scale>
            <uri>package://urdf_4/meshes/visual/Link_1.STL</uri>
          </mesh>
        </geometry>
      </visual>
    </link>
    <joint name="Joint_2" type="revolute">
      <pose relative_to="Link_1">0 0 0.1331 -1.5782 0.16406 -0.94113</pose>
      <parent>Link_1</parent>
      <child>Link_2</child>
      <axis>
        <xyz>0.044733 0 -0.999</xyz>
        <limit>
          <lower>-1.571</lower>
          <upper>1.571</upper>
          <effort>300</effort>
          <velocity>3</velocity>
        </limit>
        <dynamics>
          <spring_reference>0</spring_reference>
          <spring_stiffness>0</spring_stiffness>
        </dynamics>
      </axis>
    </joint>
    <link name="Link_2">
      <pose relative_to="Joint_2">0 0 0 0 -0 0</pose>
      <inertial>
        <pose>-0.063683 -1.7e-05 -0.003599 0 -0 0</pose>
        <mass>0.041761</mass>
        <inertia>
          <ixx>6.5036e-06</ixx>
          <ixy>-7.6644e-08</ixy>
          <ixz>-3.3324e-06</ixz>
          <iyy>7.8543e-05</iyy>
          <iyz>-2.4007e-09</iyz>
          <izz>8.0766e-05</izz>
        </inertia>
      </inertial>
      <collision name="Link_2_collision">
        <pose>0 0 0 0 -0 0</pose>
        <geometry>
          <mesh>
            <scale>1 1 1</scale>
            <uri>package://urdf_4/meshes/visual/Link_2.STL</uri>
          </mesh>
        </geometry>
      </collision>
      <visual name="Link_2_visual">
        <pose>0 0 0 0 -0 0</pose>
        <geometry>
          <mesh>
            <scale>1 1 1</scale>
            <uri>package://urdf_4/meshes/visual/Link_2.STL</uri>
          </mesh>
        </geometry>
      </visual>
    </link>
  </model>
</sdf>